<?xml version="1.0"?>
<robot xmlns:xacro="http://www.ros.org/wiki/xacro" name="diffbot">
<xacro:include filename="gazebo_control.xacro"/>
<xacro:include filename="lidar.xacro"/>
<xacro:include filename="camera.xacro"/>
<xacro:macro name="inertial_sphere" params="mass radius *origin">
        <inertial>
            <xacro:insert_block name="origin"/>
            <mass value="${mass}" />
            <inertia ixx="${(2/5) * mass * (radius*radius)}" ixy="0.0" ixz="0.0"
                    iyy="${(2/5) * mass * (radius*radius)}" iyz="0.0"
                    izz="${(2/5) * mass * (radius*radius)}" />
        </inertial>
    </xacro:macro>  

    <xacro:macro name="inertial_box" params="mass x y z *origin">
        <inertial>
            <xacro:insert_block name="origin"/>
            <mass value="${mass}" />
            <inertia ixx="${(1/12) * mass * (y*y+z*z)}" ixy="0.0" ixz="0.0"
                    iyy="${(1/12) * mass * (x*x+z*z)}" iyz="0.0"
                    izz="${(1/12) * mass * (x*x+y*y)}" />
        </inertial>
    </xacro:macro>

    <xacro:macro name="inertial_cylinder" params="mass length radius *origin">
        <inertial>
            <xacro:insert_block name="origin"/>
            <mass value="${mass}" />
            <inertia ixx="${(1/12) * mass * (3*radius*radius + length*length)}" ixy="0.0" ixz="0.0"
                    iyy="${(1/12) * mass * (3*radius*radius + length*length)}" iyz="0.0"
                    izz="${(1/2) * mass * (radius*radius)}" />
        </inertial>
    </xacro:macro>
<!--colours-->
<material name="red">
 <color rgba="1 0 0 1"/>
</material>
<material name="green">
    <color rgba="0 1 0 1"/>
</material>
<material name="black">
    <color rgba="0 0 0 1"/>
</material>
<!-- chassis-->
<link name="base_link">
</link>
<joint name="base_footprint_joint" type="fixed">
    <parent link="base_link"/>
    <child link="base_footprint"/>
    <origin xyz="0 0 0" rpy="0 0 0"/>
</joint>
<link name="base_footprint">
</link>
<joint name="chassis_joint" type="fixed">
<parent link="base_link"/>
<child link="chassis"/>
<origin xyz="-0.1 0 0"/>
</joint>
<link name="chassis">
    <visual>
        <origin xyz="0.15 0 0.075"/>
        <geometry>
            <box size="0.3 0.3 0.15"/>
        </geometry>
        <material name="red"/>
    </visual>
    <collision>
        <origin xyz="0.15 0 0.075"/>
        <geometry>
            <box size="0.3 0.3 0.15"/>
        </geometry>
    </collision>
     <xacro:inertial_box mass="0.5" x="0.3" y="0.3" z="0.15">
            <origin xyz="0.15 0 0.075" rpy="0 0 0"/>
        </xacro:inertial_box>
</link>
<gazebo reference="chassis">
            <material>Gazebo/red</material>
        </gazebo>
<!-- wheels-->
<joint name="left_wheel_joint" type="continuous">
    <parent link="chassis"/>
    <child link="left_wheel"/>
    <origin xyz="0.05 0.175 0" rpy="${pi/2} 0 0"/>
    <axis  xyz="0 0 -1"/>
</joint>
<link name="left_wheel">
    <visual>
        <geometry>
            <cylinder radius="0.06" length="0.05"/>
        </geometry>
        <material name="black"/>
    </visual>
    <collision>
        <geometry>
            <cylinder radius="0.06" length="0.05"/>
        </geometry>
    </collision>
   <xacro:inertial_cylinder mass="0.1" length="0.05" radius="0.06">
            <origin xyz="0 0 0" rpy="0 0 0"/>
        </xacro:inertial_cylinder>    
</link>
<gazebo reference="left_wheel">
            <material>Gazebo/black</material>
        </gazebo>
<joint name="right_wheel_joint" type="continuous">
    <parent link="chassis"/>
    <child link="right_wheel"/>
    <origin xyz="0.05 -0.175 0" rpy="${pi/2} 0 0"/>
    <axis xyz="0 0 -1"/>
</joint>
<link name="right_wheel">
    <visual>
        <geometry>
            <cylinder radius="0.06" length="0.05"/>
        </geometry>
        <material name="black"/>
    </visual>
    <collision>
        <geometry>
            <cylinder radius="0.06" length="0.05"/>
        </geometry>
    </collision>
   <xacro:inertial_cylinder mass="0.1" length="0.05" radius="0.06">
            <origin xyz="0 0 0" rpy="0 0 0"/>
        </xacro:inertial_cylinder>
</link>
<gazebo reference="right_wheel">
            <material>Gazebo/black</material>
        </gazebo>
<!--caster wheel-->
<joint name="caster_joint" type="fixed">
    <parent link="chassis"/>
    <child link="caster"/>
    <origin xyz="0.2 0 0"/>
</joint>
<link name="caster">
    <visual>
        <geometry>
            <sphere radius="0.06"/>
        </geometry>
        <material name="black"/>
    </visual>
    <collision>
        <geometry>
            <sphere radius="0.06"/>
        </geometry>
    </collision>
    <xacro:inertial_sphere mass="0.1" radius="0.06">
            <origin xyz="0 0 0" rpy="0 0 0"/>
        </xacro:inertial_sphere>
</link>
<gazebo reference="caster">
            <material>Gazebo/black</material>
            <mu1 value="0.0001"/>
            <mu2 value="0.0001"/>
        </gazebo>
        
</robot>
